I'm getting the following error from the worker.py whenever I submit a URL:

Traceback (most recent call last):
File "/home/a/flask-by-example/env/lib/python3.5/site-packages/rq/worker.py", line 568, in perform_job
rv = job.perform()
File "/home/a/flask-by-example/env/lib/python3.5/site-packages/rq/job.py", line 495, in perform
self._result = self.func(*self.args, **self.kwargs)
File "/home/a/flask-by-example/env/lib/python3.5/site-packages/rq/job.py", line 206, in func
return import_attribute(self.func_name)
File "/home/a/flask-by-example/env/lib/python3.5/site-packages/rq/utils.py", line 150, in import_attribute
module = importlib.import_module(module_name)
File "/usr/local/lib/python3.5/importlib/__init__.py", line 126, in import_module
return _bootstrap._gcd_import(name[level:], package, level)
File "<frozen importlib._bootstrap>", line 986, in _gcd_import
File "<frozen importlib._bootstrap>", line 969, in _find_and_load
File "<frozen importlib._bootstrap>", line 958, in _find_and_load_unlocked
File "<frozen importlib._bootstrap>", line 673, in _load_unlocked
File "<frozen importlib._bootstrap_external>", line 665, in exec_module
File "<frozen importlib._bootstrap>", line 222, in _call_with_frames_removed
File "/home/a/flask-by-example/app.py", line 21, in <module>
app.config.from_object(os.environ['APP_SETTINGS'])
File "/home/a/flask-by-example/env/lib/python3.5/site-packages/flask/config.py", line 162, in from_object
obj = import_string(obj)
File "/home/a/flask-by-example/env/lib/python3.5/site-packages/werkzeug/utils.py", line 418, in import_string
__import__(import_name)
File "/home/a/flask-by-example/config.py", line 5, in <module>
class Config(object):
File "/home/a/flask-by-example/config.py", line 10, in Config
SQLALCHEMY_DATABASE_URI = os.environ['DATABASE_URL']
File "/usr/local/lib/python3.5/os.py", line 725, in __getitem__
raise KeyError(key) from None
KeyError: 'DATABASE_URL'
Traceback (most recent call last):
File "/home/a/flask-by-example/env/lib/python3.5/site-packages/rq/worker.py", line 568, in perform_job
rv = job.perform()
File "/home/a/flask-by-example/env/lib/python3.5/site-packages/rq/job.py", line 495, in perform
self._result = self.func(*self.args, **self.kwargs)
File "/home/a/flask-by-example/env/lib/python3.5/site-packages/rq/job.py", line 206, in func
return import_attribute(self.func_name)
File "/home/a/flask-by-example/env/lib/python3.5/site-packages/rq/utils.py", line 150, in import_attribute
module = importlib.import_module(module_name)
File "/usr/local/lib/python3.5/importlib/__init__.py", line 126, in import_module
return _bootstrap._gcd_import(name[level:], package, level)
File "<frozen importlib._bootstrap>", line 986, in _gcd_import
File "<frozen importlib._bootstrap>", line 969, in _find_and_load
File "<frozen importlib._bootstrap>", line 958, in _find_and_load_unlocked
File "<frozen importlib._bootstrap>", line 673, in _load_unlocked
File "<frozen importlib._bootstrap_external>", line 665, in exec_module
File "<frozen importlib._bootstrap>", line 222, in _call_with_frames_removed
File "/home/a/flask-by-example/app.py", line 21, in <module>
app.config.from_object(os.environ['APP_SETTINGS'])
File "/home/a/flask-by-example/env/lib/python3.5/site-packages/flask/config.py", line 162, in from_object
obj = import_string(obj)
File "/home/a/flask-by-example/env/lib/python3.5/site-packages/werkzeug/utils.py", line 418, in import_string
__import__(import_name)
File "/home/a/flask-by-example/config.py", line 5, in <module>
class Config(object):
File "/home/a/flask-by-example/config.py", line 10, in Config
SQLALCHEMY_DATABASE_URI = os.environ['DATABASE_URL']
File "/usr/local/lib/python3.5/os.py", line 725, in __getitem__
raise KeyError(key) from None
KeyError: 'DATABASE_URL'

As far as I can tell redis and postgres are running.

Any help would be appreciated.